<cxx-clause id="parallel.exceptions">
  <h1>Parallel exceptions</h1>
    <cxx-section id="parallel.exceptions.behavior">
      <h1>Exception reporting behavior</h1>
        <p>
          If temporary memory resources are required by the algorithm and none are available,
          the algorithm throws a `std::bad_alloc` exception.
        </p>
        <p>
          During the execution of a standard parallel algorithm, if the application of a function
          object terminates with an uncaught exception, the behavior of the program is determined
          by the type of execution policy used to invoke the algorithm:

          <ul>
            <li>
              If the execution policy object is of type <code>vector_execution_policy</code>,
              <code>std::terminate</code> shall be called.
            </li>
            <li>
              If the execution policy object is of type <code>sequential_execution_policy</code> or
              <code>parallel_execution_policy</code>, the execution of the algorithm terminates with an
              <code>exception_list</code> exception. All uncaught exceptions thrown during
              the application of user-provided function objects shall be contained in the
              <code>exception_list</code>.

              <cxx-note>
                For example, the number of invocations of the user-provided function object in
                <code>for_each</code> is unspecified. When <code>for_each</code> is executed sequentially,
                only one exception will be contained in the <code>exception_list</code> object.
              </cxx-note>

              <cxx-note>
                These guarantees imply that, unless the algorithm has failed to allocate memory and
                terminated with <code>std::bad_alloc</code>, all exceptions thrown during the execution of
                the algorithm are communicated to the caller. It is unspecified whether an algorithm implementation will "forge ahead" after 
                encountering and capturing a user exception.
              </cxx-note>

              <cxx-note>
                The algorithm may terminate with the <code>std::bad_alloc</code> exception even if one or more
                user-provided function objects have terminated with an exception. For example, this can happen when an algorithm fails to allocate memory while
                creating or adding elements to the <code>exception_list</code> object.
              </cxx-note>
            </li>

            <li>
              If the execution policy object is of any other type, the behavior is implementation-defined.
            </li>
          </ul>
        </p>
    </cxx-section>
    <cxx-section id="parallel.exceptions.synop">
      <pre>
namespace std {
namespace experimental {
namespace parallel {
  class exception_list : public exception
  {
    public:
      typedef exception_ptr                                             value_type;
      typedef const value_type&                                         reference;
      typedef const value_type&                                         const_reference;
      typedef <em>implementation-defined</em>                                    const_iterator;
      typedef const_iterator                                            iterator;
<ins>      typedef typename iterator_traits<const_iterator>::difference_type                 difference_type;</ins>
      typedef size_t                                                    size_type;
  
<del>      size_t size() const;</del>
<ins>      size_t size() const noexcept;</ins>
<del>      iterator begin() const;</del>
<ins>      iterator begin() const noexcept;</ins>
<del>      iterator end() const;</del>
<ins>      iterator end() const noexcept;</ins>
  
    private:
      std::list&lt;exception_ptr&gt; exceptions_; // exposition only
  };
}
}
}
      </pre>

      <p>
        The class <code>exception_list</code> is a container of <code>exception_ptr</code> objects parallel
        algorithms may use to communicate uncaught exceptions encountered during parallel execution to the
        caller of the algorithm.
      </p>

      <p>
        <ins>The type <code>exception_list::const_iterator</code> shall fulfill the requirements of
        <code>ForwardIterator</code></ins>.
      </p>

      <cxx-function>
        <cxx-signature>
          size_t size() const <ins>noexcept</ins>;
        </cxx-signature>

        <cxx-returns>
          The number of <code>exception_ptr</code> objects contained within the <code>exception_list</code>.
        </cxx-returns>

        <cxx-complexity>
          Constant time.
        </cxx-complexity>
      </cxx-function>

      <cxx-function>
        <cxx-signature>
          exception_list::iterator begin() const <ins>noexcept</ins>;
        </cxx-signature>

        <cxx-returns>
          An iterator referring to the first <code>exception_ptr</code> object contained within the <code>exception_list</code>.
        </cxx-returns>
      </cxx-function>

      <cxx-function>
        <cxx-signature>
          exception_list::iterator end() const <ins>noexcept</ins>;
        </cxx-signature>

        <cxx-returns>
          An iterator which is the past-the-end value for the <code>exception_list</code>.
        </cxx-returns>
      </cxx-function>
    </cxx-section>
</cxx-clause>
